<robot name="dexhand021_left">

  <mujoco>
    <compiler meshdir="../meshes/dexhand021" balanceinertia="true" discardvisual="false" />
  </mujoco>

  <link name="left_hand_base" />

  <joint name="left_base_to_hand" type="fixed">
    <parent link="left_hand_base" />
    <child link="l_p_link0" />
    <origin xyz="0. 0. -0.17" rpy="0 0 1.57" />
  </joint>

  <link name="l_p_link0">
    <inertial>
      <origin xyz="-0.0005340340782799666 -0.0030739671736089423 0.2580979226195014" rpy="0 0 0" />
      <mass value="0.4582127297726252" />
      <inertia ixx="0.0008682603987855573" ixy="-4.647872477702509e-06"
        ixz="-1.9994715059692555e-06" iyy="0.0011955717530257226" iyz="4.26720458052884e-05"
        izz="0.00046834351454589116" />
    </inertial>
    <visual>
      <origin xyz="0 0 0" rpy="0 0 0" />
      <geometry>
        <mesh filename="../meshes/dexhand021/l_p_link0.STL" />
      </geometry>
      <material name="">
        <color rgba="0.3 0.3 0.3 1" />
      </material>
    </visual>
    <collision>
      <origin xyz="0 0 0" rpy="0 0 0" />
      <geometry>
        <mesh filename="../meshes/dexhand021/l_p_link0.STL" />
      </geometry>
    </collision>
  </link>

  <link name="l_f_link1_1">
    <inertial>
      <origin xyz="0.002052234666759825 -0.005273334526360467 -0.017766417143674378" rpy="0 0 0" />
      <mass value="0.005180345836222872" />
      <inertia ixx="1.1430624429635148e-06" ixy="-2.1632825990418803e-08"
        ixz="-9.945444780275452e-08" iyy="1.1661466974877877e-06" iyz="-2.1793835308526277e-07"
        izz="3.1537914003827447e-07" />
    </inertial>
    <visual>
      <origin xyz="0 0 0" rpy="0 0 0" />
      <geometry>
        <mesh filename="../meshes/dexhand021/l_f_link1_1.STL" />
      </geometry>
      <material name="">
        <color rgba="0.3 0.3 0.3 1" />
      </material>
    </visual>
    <collision>
      <origin xyz="0 0 0" rpy="0 0 0" />
      <geometry>
        <mesh filename="../meshes/dexhand021/l_f_link1_1.STL" />
      </geometry>
    </collision>
  </link>

  <joint name="l_f_joint1_1" type="revolute">
    <origin xyz="-0.023855 -0.031204 0.27607" rpy="0 -0.15197 -2.8876" />
    <parent link="l_p_link0" />
    <child link="l_f_link1_1" />
    <axis xyz="0 0.26521 0.96419" />
    <limit lower="0" upper="2.2" effort="10" velocity="1.5" />
    <joint_properties damping="0.3" friction="0.5" />
  </joint>

  <link name="l_f_link1_2">
    <inertial>
      <origin xyz="0.021535504665713627 0.000506377639770679 -0.0008142325238397076" rpy="0 0 0" />
      <mass value="0.005145873046733005" />
      <inertia ixx="2.0955625734077272e-07" ixy="-9.153029438540082e-09"
        ixz="1.1384864653981019e-10" iyy="1.060406958470173e-06" iyz="-1.130625438040032e-09"
        izz="1.044207336185289e-06" />
    </inertial>
    <visual>
      <origin xyz="0 0 0" rpy="0 0 0" />
      <geometry>
        <mesh filename="../meshes/dexhand021/l_f_link1_2.STL" />
      </geometry>
      <material name="">
        <color rgba="0.3 0.3 0.3 1" />
      </material>
    </visual>
    <collision>
      <origin xyz="0 0 0" rpy="0 0 0" />
      <geometry>
        <mesh filename="../meshes/dexhand021/l_f_link1_2.STL" />
      </geometry>
    </collision>
  </link>

  <joint name="l_f_joint1_2" type="revolute">
    <origin xyz="0.0083307 0 0" rpy="1.30243 -0.018415 0.0050658" />
    <parent link="l_f_link1_1" />
    <child link="l_f_link1_2" />
    <axis xyz="0 0 1" />
    <limit lower="0" upper="1.3" effort="10" velocity="1.5" />
    <joint_properties damping="0.3" friction="0.6" />
  </joint>

  <link name="l_f_link1_3">
    <inertial>
      <origin xyz="0.013223206653742587 0.0007239105528827508 -0.0012977744957348464" rpy="0 0 0" />
      <mass value="0.003510129470235022" />
      <inertia ixx="1.0264326739891652e-07" ixy="-1.0034384004261486e-08"
        ixz="1.537174856934156e-09" iyy="3.145228617298639e-07" iyz="-3.5848718337208966e-11"
        izz="3.260539360948065e-07" />
    </inertial>
    <visual>
      <origin xyz="0 0 0" rpy="3.14 0 0" />
      <geometry>
        <mesh filename="../meshes/dexhand021/l_f_link1_3.STL" />
      </geometry>
      <material name="">
        <color rgba="0.3 0.3 0.3 1" />
      </material>
    </visual>
    <collision>
      <origin xyz="0 0 0" rpy="3.14 0 0" />
      <geometry>
        <mesh filename="../meshes/dexhand021/l_f_link1_3.STL" />
      </geometry>
    </collision>
  </link>

  <joint name="l_f_joint1_3" type="revolute">
    <origin xyz="0.043 0 0" rpy="0 0 0" />
    <parent link="l_f_link1_2" />
    <child link="l_f_link1_3" />
    <axis xyz="0 0 1" />
    <limit lower="0" upper="1.3" effort="10" velocity="1.5" />
    <joint_properties damping="0.3" friction="0.6" />
  </joint>

  <link name="l_f_link1_4">
    <inertial>
      <origin xyz="0.016827162591071785 0.002542844173764781 -0.0012898514109792828" rpy="0 0 0" />
      <mass value="0.004357667635534957" />
      <inertia ixx="1.7288868644056656e-07" ixy="-7.193280428920156e-08"
        ixz="-9.525535641984676e-11" iyy="5.475564752014148e-07" iyz="-4.665173458394984e-11"
        izz="5.333289098973524e-07" />
    </inertial>
    <visual>
      <origin xyz="0 0 0" rpy="3.14 0 0" />
      <geometry>
        <mesh filename="../meshes/dexhand021/l_f_link1_4.STL" />
      </geometry>
      <material name="">
        <color rgba="0.3 0.3 0.3 1" />
      </material>
    </visual>
    <collision>
      <origin xyz="0 0 0" rpy="3.14 0 0" />
      <geometry>
        <mesh filename="../meshes/dexhand021/l_f_link1_4.STL" />
      </geometry>
    </collision>
  </link>

  <joint name="l_f_joint1_4" type="revolute">
    <origin xyz="0.025 0 0" rpy="0 0 0" />
    <parent link="l_f_link1_3" />
    <child link="l_f_link1_4" />
    <axis xyz="0 0 1" />
    <limit lower="0" upper="1.3" effort="10" velocity="1.5" />
    <joint_properties damping="0.3" friction="0.6" />
  </joint>

  <link name="l_f_link1_4_1">
    <inertial>
      <origin xyz="0.00976545037672086 -0.006088691115389994 -0.0012928496119325166" rpy="0 0 0" />
      <mass value="0.0003728592379595507" />
      <inertia ixx="1.0806913723931537e-08" ixy="1.4343552260771358e-10"
        ixz="-7.904655850851082e-13" iyy="1.2799737605046901e-08" iyz="9.706813447028242e-14"
        izz="2.9719855154096667e-09" />
    </inertial>
    <visual>
      <origin xyz="0 0 0" rpy="3.14 0 0" />
      <geometry>
        <mesh filename="../meshes/dexhand021/l_f_link1_4_1.STL" />
      </geometry>
      <material name="">
        <color rgba="0.3 0.3 0.3 1" />
      </material>
    </visual>
    <collision>
      <origin xyz="0 0 0" rpy="3.14 0 0" />
      <geometry>
        <mesh filename="../meshes/dexhand021/l_f_link1_4_1.STL" />
      </geometry>
    </collision>
  </link>

  <joint name="l_f_joint1_4_1" type="fixed">
    <origin xyz="0 0 0" rpy="0 0 0" />
    <parent link="l_f_link1_4" />
    <child link="l_f_link1_4_1" />
    <axis xyz="0 0 0" />
  </joint>

  <link name="l_f_link1_4_2">
    <inertial>
      <origin xyz="0.015433183993485528 0.006148726662184262 -0.0012940973222225634" rpy="0 0 0" />
      <mass value="0.0019468120967671353" />
      <inertia ixx="1.4302400339125914e-07" ixy="-4.887309828405806e-08" ixz="5.685919131349908e-11"
        iyy="3.26257386209023e-07" iyz="7.480451441953261e-12" izz="2.8666011571660654e-07" />
    </inertial>
    <visual>
      <origin xyz="0 0 0" rpy="3.14 0 0" />
      <geometry>
        <mesh filename="../meshes/dexhand021/l_f_link1_4_2.STL" />
      </geometry>
      <material name="">
        <color rgba="0.9 0.9 0.9 1" />
      </material>
    </visual>
    <collision>
      <origin xyz="0 0 0" rpy="3.14 0 0" />
      <geometry>
        <mesh filename="../meshes/dexhand021/l_f_link1_4_2.STL" />
      </geometry>
    </collision>
  </link>

  <joint name="l_f_joint1_4_2" type="fixed">
    <origin xyz="0 0 0" rpy="0 0 0" />
    <parent link="l_f_link1_4" />
    <child link="l_f_link1_4_2" />
    <axis xyz="0 0 0" />
  </joint>

  <link name="l_f_link1_3_1">
    <inertial>
      <origin xyz="0.012419626621347997 -0.007723681641112162 -0.001292035727648269" rpy="0 0 0" />
      <mass value="0.0004927439497821334" />
      <inertia ixx="1.4812698827671582e-08" ixy="2.462530333018401e-10" ixz="5.204752318795197e-13"
        iyy="1.6886270323136902e-08" iyz="-7.055265282688354e-13" izz="4.8400028799418825e-09" />
    </inertial>
    <visual>
      <origin xyz="0 0 0" rpy="3.14 0 0" />
      <geometry>
        <mesh filename="../meshes/dexhand021/l_f_link1_3_1.STL" />
      </geometry>
      <material name="">
        <color rgba="0.3 0.3 0.3 1" />
      </material>
    </visual>
    <collision>
      <origin xyz="0 0 0" rpy="3.14 0 0" />
      <geometry>
        <mesh filename="../meshes/dexhand021/l_f_link1_3_1.STL" />
      </geometry>
    </collision>
  </link>

  <joint name="l_f_joint1_3_1" type="fixed">
    <origin xyz="0 0 0" rpy="0 0 0" />
    <parent link="l_f_link1_3" />
    <child link="l_f_link1_3_1" />
    <axis xyz="0 0 0" />
  </joint>

  <link name="l_f_link1_3_2">
    <inertial>
      <origin xyz="0.012938038149695234 0.004966116981932351 -0.0012957151384533254" rpy="0 0 0" />
      <mass value="0.0009264867224319483" />
      <inertia ixx="5.3427012938718874e-08" ixy="-7.101425075294421e-10" ixz="1.771926549530019e-12"
        iyy="7.062474289204522e-08" iyz="1.4720413014316507e-12" izz="4.7550430803969935e-08" />
    </inertial>
    <visual>
      <origin xyz="0 0 0" rpy="3.14 0 0" />
      <geometry>
        <mesh filename="../meshes/dexhand021/l_f_link1_3_2.STL" />
      </geometry>
      <material name="">
        <color rgba="0.9 0.9 0.9 1" />
      </material>
    </visual>
    <collision>
      <origin xyz="0 0 0" rpy="3.14 0 0" />
      <geometry>
        <mesh filename="../meshes/dexhand021/l_f_link1_3_2.STL" />
      </geometry>
    </collision>
  </link>

  <joint name="l_f_joint1_3_2" type="fixed">
    <origin xyz="0 0 0" rpy="0 0 0" />
    <parent link="l_f_link1_3" />
    <child link="l_f_link1_3_2" />
    <axis xyz="0 0 0" />
  </joint>

  <link name="l_f_link1_2_1">
    <inertial>
      <origin xyz="0.020433667197651627 -0.009511001235208358 -0.0012923408126536344" rpy="0 0 0" />
      <mass value="0.001635471969222149" />
      <inertia ixx="4.406768581014031e-08" ixy="-3.6957813553952664e-09"
        ixz="-6.271444654441986e-12" iyy="9.649204412564006e-08" iyz="-3.0566461653670558e-12"
        izz="6.793850270150975e-08" />
    </inertial>
    <visual>
      <origin xyz="0 0 0" rpy="3.14 0 0" />
      <geometry>
        <mesh filename="../meshes/dexhand021/l_f_link1_2_1.STL" />
      </geometry>
      <material name="">
        <color rgba="0.3 0.3 0.3 1" />
      </material>
    </visual>
    <collision>
      <origin xyz="0 0 0" rpy="3.14 0 0" />
      <geometry>
        <mesh filename="../meshes/dexhand021/l_f_link1_2_1.STL" />
      </geometry>
    </collision>
  </link>

  <joint name="l_f_joint1_2_1" type="fixed">
    <origin xyz="0 0 0" rpy="0 0 0" />
    <parent link="l_f_link1_2" />
    <child link="l_f_link1_2_1" />
    <axis xyz="0 0 0" />
  </joint>

  <link name="l_f_link1_2_2">
    <inertial>
      <origin xyz="0.022921501261816545 0.0027716306188103625 -0.0012979021572152708" rpy="0 0 0" />
      <mass value="0.002536590997261413" />
      <inertia ixx="2.2859663761882353e-07" ixy="-1.3411101520302956e-08"
        ixz="-3.0992878304785846e-10" iyy="6.01449052592349e-07" iyz="9.341938224099394e-11"
        izz="5.304297061779193e-07" />
    </inertial>
    <visual>
      <origin xyz="0 0 0" rpy="3.14 0 0" />
      <geometry>
        <mesh filename="../meshes/dexhand021/l_f_link1_2_2.STL" />
      </geometry>
      <material name="">
        <color rgba="0.9 0.9 0.9 1" />
      </material>
    </visual>
    <collision>
      <origin xyz="0 0 0" rpy="3.14 0 0" />
      <geometry>
        <mesh filename="../meshes/dexhand021/l_f_link1_2_2.STL" />
      </geometry>
    </collision>
  </link>

  <joint name="l_f_joint1_2_2" type="fixed">
    <origin xyz="0 0 0" rpy="0 0 0" />
    <parent link="l_f_link1_2" />
    <child link="l_f_link1_2_2" />
    <axis xyz="0 0 0" />
  </joint>

  <link name="l_f_link2_1">
    <inertial>
      <origin xyz="0.008006862264851176 1.8338547498861026e-05 -0.0015842278483306311" rpy="0 0 0" />
      <mass value="0.0035185790405732886" />
      <inertia ixx="2.306698980023173e-07" ixy="-8.218664123414487e-10" ixz="4.890426922121152e-08"
        iyy="3.7198481294084705e-07" iyz="-1.596272919287658e-10" izz="2.98005291680277e-07" />
    </inertial>
    <visual>
      <origin xyz="0 0 0" rpy="0 0 0" />
      <geometry>
        <mesh filename="../meshes/dexhand021/l_f_link2_1.STL" />
      </geometry>
      <material name="">
        <color rgba="0.3 0.3 0.3 1" />
      </material>
    </visual>
    <collision>
      <origin xyz="0 0 0" rpy="0 0 0" />
      <geometry>
        <mesh filename="../meshes/dexhand021/l_f_link2_1.STL" />
      </geometry>
    </collision>
  </link>

  <joint name="l_f_joint2_1" type="revolute">
    <origin xyz="-0.034912 -0.005466 0.3287" rpy="-1.5708 -1.5708 3.1416" />
    <parent link="l_p_link0" />
    <child link="l_f_link2_1" />
    <axis xyz="0 0 1" />
    <limit lower="0" upper="0.6" effort="10" velocity="1.5" />
    <joint_properties damping="0.3" friction="0.6" />
  </joint>

  <link name="l_f_link2_2">
    <inertial>
      <origin xyz="0.0214446795509066 -0.00046289490893132847 -0.000478692708976815" rpy="0 0 0" />
      <mass value="0.004989367448655121" />
      <inertia ixx="2.06447639113428e-07" ixy="8.780455972481956e-09" ixz="-2.955798697224877e-10"
        iyy="1.055201474830906e-06" iyz="-9.019287841410613e-10" izz="1.0401625323233744e-06" />
    </inertial>
    <visual>
      <origin xyz="0 0 0" rpy="0 0 0" />
      <geometry>
        <mesh filename="../meshes/dexhand021/l_f_link2_2.STL" />
      </geometry>
      <material name="">
        <color rgba="0.3 0.3 0.3 1" />
      </material>
    </visual>
    <collision>
      <origin xyz="0 0 0" rpy="0 0 0" />
      <geometry>
        <mesh filename="../meshes/dexhand021/l_f_link2_2.STL" />
      </geometry>
    </collision>
  </link>

  <joint name="l_f_joint2_2" type="revolute">
    <origin xyz="0.017 0 0" rpy="1.5708 0 0" />
    <parent link="l_f_link2_1" />
    <child link="l_f_link2_2" />
    <axis xyz="0 0 1" />
    <limit lower="0" upper="1.3" effort="10" velocity="1.5" />
    <joint_properties damping="0.3" friction="0.6" />
  </joint>

  <link name="l_f_link2_3">
    <inertial>
      <origin xyz="0.013280328692676044 -0.0006199315921701265 -1.7863321659867604e-05" rpy="0 0 0" />
      <mass value="0.003320332898413456" />
      <inertia ixx="9.569221204956009e-08" ixy="1.0826362598447572e-08"
        ixz="-1.6181713632700241e-09" iyy="3.07789315922064e-07" iyz="-8.827964273946318e-11"
        izz="3.2064040293000583e-07" />
    </inertial>
    <visual>
      <origin xyz="0 0 0" rpy="0 0 0" />
      <geometry>
        <mesh filename="../meshes/dexhand021/l_f_link2_3.STL" />
      </geometry>
      <material name="">
        <color rgba="0.3 0.3 0.3 1" />
      </material>
    </visual>
    <collision>
      <origin xyz="0 0 0" rpy="0 0 0" />
      <geometry>
        <mesh filename="../meshes/dexhand021/l_f_link2_3.STL" />
      </geometry>
    </collision>
  </link>

  <joint name="l_f_joint2_3" type="revolute">
    <origin xyz="0.043 0 0" rpy="0 0 0" />
    <parent link="l_f_link2_2" />
    <child link="l_f_link2_3" />
    <axis xyz="0 0 1" />
    <limit lower="0" upper="1.3" effort="10" velocity="1.5" />
    <joint_properties damping="0.3" friction="0.6" />
  </joint>

  <link name="l_f_link2_4">
    <inertial>
      <origin xyz="0.01683572414258611 -0.0025451338947223125 -2.3757913786070927e-06" rpy="0 0 0" />
      <mass value="0.004352952819276659" />
      <inertia ixx="1.7269823390949173e-07" ixy="7.185121764726582e-08" ixz="1.0129621607900475e-10"
        iyy="5.470938126961464e-07" iyz="-4.584118209251816e-11" izz="5.330028956954253e-07" />
    </inertial>
    <visual>
      <origin xyz="0 0 0" rpy="0 0 0" />
      <geometry>
        <mesh filename="../meshes/dexhand021/l_f_link2_4.STL" />
      </geometry>
      <material name="">
        <color rgba="0.3 0.3 0.3 1" />
      </material>
    </visual>
    <collision>
      <origin xyz="0 0 0" rpy="0 0 0" />
      <geometry>
        <mesh filename="../meshes/dexhand021/l_f_link2_4.STL" />
      </geometry>
    </collision>
  </link>

  <joint name="l_f_joint2_4" type="revolute">
    <origin xyz="0.025 0 0" rpy="0 0 0" />
    <parent link="l_f_link2_3" />
    <child link="l_f_link2_4" />
    <axis xyz="0 0 1" />
    <limit lower="0" upper="1.3" effort="10" velocity="1.5" />
    <joint_properties damping="0.3" friction="0.6" />
  </joint>

  <link name="l_f_link2_4_1">
    <inertial>
      <origin xyz="0.009738422454345731 0.005930029867607995 5.184464520528353e-07" rpy="0 0 0" />
      <mass value="0.0003894330192680041" />
      <inertia ixx="1.1761888706684735e-08" ixy="-1.9209378388774791e-10"
        ixz="1.1862845669527616e-12" iyy="1.3432121470992003e-08" iyz="1.5284533403935e-13"
        izz="3.3280605709656387e-09" />
    </inertial>
    <visual>
      <origin xyz="0 0 0" rpy="0 0 0" />
      <geometry>
        <mesh filename="../meshes/dexhand021/l_f_link2_4_1.STL" />
      </geometry>
      <material name="">
        <color rgba="0.3 0.3 0.3 1" />
      </material>
    </visual>
    <collision>
      <origin xyz="0 0 0" rpy="0 0 0" />
      <geometry>
        <mesh filename="../meshes/dexhand021/l_f_link2_4_1.STL" />
      </geometry>
    </collision>
  </link>

  <joint name="l_f_joint2_4_1" type="fixed">
    <origin xyz="0 0 0" rpy="0 0 0" />
    <parent link="l_f_link2_4" />
    <child link="l_f_link2_4_1" />
    <axis xyz="0 0 0" />
  </joint>

  <link name="l_f_link2_4_2">
    <inertial>
      <origin xyz="0.015433183879573308 -0.006148726613435803 1.6634833668023471e-06" rpy="0 0 0" />
      <mass value="0.0019468121678303382" />
      <inertia ixx="1.43024055038343e-07" ixy="4.887309883330071e-08" ixz="-5.680610238538469e-11"
        iyy="3.262574396877791e-07" iyz="7.694528620463915e-12" izz="2.866601186965881e-07" />
    </inertial>
    <visual>
      <origin xyz="0 0 0" rpy="0 0 0" />
      <geometry>
        <mesh filename="../meshes/dexhand021/l_f_link2_4_2.STL" />
      </geometry>
      <material name="">
        <color rgba="0.9 0.9 0.9 1" />
      </material>
    </visual>
    <collision>
      <origin xyz="0 0 0" rpy="0 0 0" />
      <geometry>
        <mesh filename="../meshes/dexhand021/l_f_link2_4_2.STL" />
      </geometry>
    </collision>
  </link>

  <joint name="l_f_joint2_4_2" type="fixed">
    <origin xyz="0 0 0" rpy="0 0 0" />
    <parent link="l_f_link2_4" />
    <child link="l_f_link2_4_2" />
    <axis xyz="0 0 0" />
  </joint>

  <link name="l_f_link2_3_1">
    <inertial>
      <origin xyz="0.012402519029567715 0.00771492069507075 1.7558889501829423e-09" rpy="0 0 0" />
      <mass value="0.0004998303821989263" />
      <inertia ixx="1.512425582589371e-08" ixy="-2.547965438972332e-10" ixz="1.4306517121720027e-13"
        iyy="1.713520438388161e-08" iyz="-1.9604892906129062e-13" izz="4.9359960447247895e-09" />
    </inertial>
    <visual>
      <origin xyz="0 0 0" rpy="0 0 0" />
      <geometry>
        <mesh filename="../meshes/dexhand021/l_f_link2_3_1.STL" />
      </geometry>
      <material name="">
        <color rgba="0.3 0.3 0.3 1" />
      </material>
    </visual>
    <collision>
      <origin xyz="0 0 0" rpy="0 0 0" />
      <geometry>
        <mesh filename="../meshes/dexhand021/l_f_link2_3_1.STL" />
      </geometry>
    </collision>
  </link>

  <joint name="l_f_joint2_3_1" type="fixed">
    <origin xyz="0 0 0" rpy="0 0 0" />
    <parent link="l_f_link2_3" />
    <child link="l_f_link2_3_1" />
    <axis xyz="0 0 0" />
  </joint>

  <link name="l_f_link2_3_2">
    <inertial>
      <origin xyz="0.012938248197779318 -0.004966379635972428 -5.799490468624966e-07" rpy="0 0 0" />
      <mass value="0.0009265838824928249" />
      <inertia ixx="5.3433679145874956e-08" ixy="7.112721953916162e-10" ixz="4.756436715934301e-12"
        iyy="7.063684996215479e-08" iyz="-9.602248319373438e-13" izz="4.7559278625456466e-08" />
    </inertial>
    <visual>
      <origin xyz="0 0 0" rpy="0 0 0" />
      <geometry>
        <mesh filename="../meshes/dexhand021/l_f_link2_3_2.STL" />
      </geometry>
      <material name="">
        <color rgba="0.9 0.9 0.9 1" />
      </material>
    </visual>
    <collision>
      <origin xyz="0 0 0" rpy="0 0 0" />
      <geometry>
        <mesh filename="../meshes/dexhand021/l_f_link2_3_2.STL" />
      </geometry>
    </collision>
  </link>

  <joint name="l_f_joint2_3_2" type="fixed">
    <origin xyz="0 0 0" rpy="0 0 0" />
    <parent link="l_f_link2_3" />
    <child link="l_f_link2_3_2" />
    <axis xyz="0 0 0" />
  </joint>

  <link name="l_f_link2_2_1">
    <inertial>
      <origin xyz="0.02037738640824138 0.008105578472303551 -1.835825070530908e-09" rpy="0 0 0" />
      <mass value="0.0009340644343591185" />
      <inertia ixx="2.7202530997589015e-08" ixy="2.318830577727918e-09" ixz="1.4872477534369214e-12"
        iyy="6.511791793427609e-08" iyz="-3.0048229353993707e-14" izz="4.166928950170176e-08" />
    </inertial>
    <visual>
      <origin xyz="0 0 0" rpy="0 0 0" />
      <geometry>
        <mesh filename="../meshes/dexhand021/l_f_link2_2_1.STL" />
      </geometry>
      <material name="">
        <color rgba="0.3 0.3 0.3 1" />
      </material>
    </visual>
    <collision>
      <origin xyz="0 0 0" rpy="0 0 0" />
      <geometry>
        <mesh filename="../meshes/dexhand021/l_f_link2_2_1.STL" />
      </geometry>
    </collision>
  </link>

  <joint name="l_f_joint2_2_1" type="fixed">
    <origin xyz="0 0 0" rpy="0 0 0" />
    <parent link="l_f_link2_2" />
    <child link="l_f_link2_2_1" />
    <axis xyz="0 0 0" />
  </joint>

  <link name="l_f_link2_2_2">
    <inertial>
      <origin xyz="0.021873800021581503 -0.0029659448659418437 3.42654186750297e-06" rpy="0 0 0" />
      <mass value="0.002679962972544191" />
      <inertia ixx="2.461062629334218e-07" ixy="5.789691111700682e-09" ixz="1.382548386170286e-10"
        iyy="6.71303134378717e-07" iyz="6.228665402457969e-11" izz="5.922202883500984e-07" />
    </inertial>
    <visual>
      <origin xyz="0 0 0" rpy="0 0 0" />
      <geometry>
        <mesh filename="../meshes/dexhand021/l_f_link2_2_2.STL" />
      </geometry>
      <material name="">
        <color rgba="0.9 0.9 0.9 1" />
      </material>
    </visual>
    <collision>
      <origin xyz="0 0 0" rpy="0 0 0" />
      <geometry>
        <mesh filename="../meshes/dexhand021/l_f_link2_2_2.STL" />
      </geometry>
    </collision>
  </link>

  <joint name="l_f_joint2_2_2" type="fixed">
    <origin xyz="0 0 0" rpy="0 0 0" />
    <parent link="l_f_link2_2" />
    <child link="l_f_link2_2_2" />
    <axis xyz="0 0 0" />
  </joint>

  <link name="l_f_link3_1">
    <inertial>
      <origin xyz="0.008006845862113532 2.4430781986466193e-05 -0.0015842278418640794" rpy="0 0 0" />
      <mass value="0.0035185790775859407" />
      <inertia ixx="2.306712335434569e-07" ixy="-9.293912036503249e-10" ixz="4.8904375973568323e-08"
        iyy="3.7198348184027887e-07" iyz="-1.2241591577587476e-10" izz="2.98005295591405e-07" />
    </inertial>
    <visual>
      <origin xyz="0 0 0" rpy="0 0 0" />
      <geometry>
        <mesh filename="../meshes/dexhand021/l_f_link3_1.STL" />
      </geometry>
      <material name="">
        <color rgba="0.3 0.3 0.3 1" />
      </material>
    </visual>
    <collision>
      <origin xyz="0 0 0" rpy="0 0 0" />
      <geometry>
        <mesh filename="../meshes/dexhand021/l_f_link3_1.STL" />
      </geometry>
    </collision>
  </link>

  <joint name="l_f_joint3_1" type="revolute">
    <origin xyz="-0.010612 -0.005466 0.3377" rpy="1.5708 -1.57 0" />
    <parent link="l_p_link0" />
    <child link="l_f_link3_1" />
    <axis xyz="0 0 1" />
    <limit lower="-0.001" upper="0.001" effort="10" velocity="1.5" />
  </joint>

  <link name="l_f_link3_2">
    <inertial>
      <origin xyz="0.021444679550906676 -0.000462894908931048 -0.0004786927089766434" rpy="0 0 0" />
      <mass value="0.004989367448655343" />
      <inertia ixx="2.064476391134477e-07" ixy="8.780455972508192e-09" ixz="-2.9557986970972456e-10"
        iyy="1.0552014748310246e-06" iyz="-9.019287841432917e-10" izz="1.0401625323234898e-06" />
    </inertial>
    <visual>
      <origin xyz="0 0 0" rpy="0 0 0" />
      <geometry>
        <mesh filename="../meshes/dexhand021/l_f_link3_2.STL" />
      </geometry>
      <material name="">
        <color rgba="0.3 0.3 0.3 1" />
      </material>
    </visual>
    <collision>
      <origin xyz="0 0 0" rpy="0 0 0" />
      <geometry>
        <mesh filename="../meshes/dexhand021/l_f_link3_2.STL" />
      </geometry>
    </collision>
  </link>

  <joint name="l_f_joint3_2" type="revolute">
    <origin xyz="0.017 1.2935E-05 0" rpy="1.5708 0 0.00076086" />
    <parent link="l_f_link3_1" />
    <child link="l_f_link3_2" />
    <axis xyz="0 0 1" />
    <limit lower="0" upper="1.3" effort="10" velocity="1.5" />
    <joint_properties damping="0.3" friction="0.6" />
  </joint>

  <link name="l_f_link3_3">
    <inertial>
      <origin xyz="0.013280328692675118 -0.0006199315921702535 -1.7863321659824415e-05" rpy="0 0 0" />
      <mass value="0.0033203328984136053" />
      <inertia ixx="9.569221204956855e-08" ixy="1.0826362598447793e-08"
        ixz="-1.6181713632650656e-09" iyy="3.077893159220978e-07" iyz="-8.827964274264422e-11"
        izz="3.206404029300517e-07" />
    </inertial>
    <visual>
      <origin xyz="0 0 0" rpy="0 0 0" />
      <geometry>
        <mesh filename="../meshes/dexhand021/l_f_link3_3.STL" />
      </geometry>
      <material name="">
        <color rgba="0.3 0.3 0.3 1" />
      </material>
    </visual>
    <collision>
      <origin xyz="0 0 0" rpy="0 0 0" />
      <geometry>
        <mesh filename="../meshes/dexhand021/l_f_link3_3.STL" />
      </geometry>
    </collision>
  </link>

  <joint name="l_f_joint3_3" type="revolute">
    <origin xyz="0.043 0 0" rpy="0 0 0" />
    <parent link="l_f_link3_2" />
    <child link="l_f_link3_3" />
    <axis xyz="0 0 1" />
    <limit lower="0" upper="1.3" effort="10" velocity="1.5" />
    <joint_properties damping="0.3" friction="0.6" />
  </joint>

  <link name="l_f_link3_4">
    <inertial>
      <origin xyz="0.01683572414297905 -0.002545133895002117 -2.375791299186665e-06" rpy="0 0 0" />
      <mass value="0.004352952819355013" />
      <inertia ixx="1.726982339129985e-07" ixy="7.185121765660968e-08" ixz="1.012962108441861e-10"
        iyy="5.47093812718992e-07" iyz="-4.5841181436562026e-11" izz="5.330028957234555e-07" />
    </inertial>
    <visual>
      <origin xyz="0 0 0" rpy="0 0 0" />
      <geometry>
        <mesh filename="../meshes/dexhand021/l_f_link3_4.STL" />
      </geometry>
      <material name="">
        <color rgba="0.3 0.3 0.3 1" />
      </material>
    </visual>
    <collision>
      <origin xyz="0 0 0" rpy="0 0 0" />
      <geometry>
        <mesh filename="../meshes/dexhand021/l_f_link3_4.STL" />
      </geometry>
    </collision>
  </link>

  <joint name="l_f_joint3_4" type="revolute">
    <origin xyz="0.025 0 0" rpy="0 0 0" />
    <parent link="l_f_link3_3" />
    <child link="l_f_link3_4" />
    <axis xyz="0 0 1" />
    <limit lower="0" upper="1.3" effort="10" velocity="1.5" />
    <joint_properties damping="0.3" friction="0.6" />
  </joint>

  <link name="l_f_link3_4_1">
    <inertial>
      <origin xyz="0.00973842245459893 0.005930029867598805 5.184462258307792e-07" rpy="0 0 0" />
      <mass value="0.00038943301930773646" />
      <inertia ixx="1.1761888707777e-08" ixy="-1.9209378388076858e-10" ixz="1.1862851425341784e-12"
        iyy="1.3432121472446845e-08" iyz="1.5284543351379645e-13" izz="3.328060571257918e-09" />
    </inertial>
    <visual>
      <origin xyz="0 0 0" rpy="0 0 0" />
      <geometry>
        <mesh filename="../meshes/dexhand021/l_f_link3_4_1.STL" />
      </geometry>
      <material name="">
        <color rgba="0.3 0.3 0.3 1" />
      </material>
    </visual>
    <collision>
      <origin xyz="0 0 0" rpy="0 0 0" />
      <geometry>
        <mesh filename="../meshes/dexhand021/l_f_link3_4_1.STL" />
      </geometry>
    </collision>
  </link>

  <joint name="l_f_joint3_4_1" type="fixed">
    <origin xyz="0 0 0" rpy="0 0 0" />
    <parent link="l_f_link3_4" />
    <child link="l_f_link3_4_1" />
    <axis xyz="0 0 0" />
  </joint>

  <link name="l_f_link3_4_2">
    <inertial>
      <origin xyz="0.015433183877996647 -0.006148726613474619 1.663483296615289e-06" rpy="0 0 0" />
      <mass value="0.0019468121676849014" />
      <inertia ixx="1.4302405503805395e-07" ixy="4.8873098834891334e-08"
        ixz="-5.6806099502751205e-11" iyy="3.262574396227581e-07" iyz="7.694528690012234e-12"
        izz="2.866601186317795e-07" />
    </inertial>
    <visual>
      <origin xyz="0 0 0" rpy="0 0 0" />
      <geometry>
        <mesh filename="../meshes/dexhand021/l_f_link3_4_2.STL" />
      </geometry>
      <material name="">
        <color rgba="0.9 0.9 0.9 1" />
      </material>
    </visual>
    <collision>
      <origin xyz="0 0 0" rpy="0 0 0" />
      <geometry>
        <mesh filename="../meshes/dexhand021/l_f_link3_4_2.STL" />
      </geometry>
    </collision>
  </link>

  <joint name="l_f_joint3_4_2" type="fixed">
    <origin xyz="0 0 0" rpy="0 0 0" />
    <parent link="l_f_link3_4" />
    <child link="l_f_link3_4_2" />
    <axis xyz="0 0 0" />
    <joint_properties damping="0.3" friction="0.6" />
  </joint>

  <link name="l_f_link3_3_1">
    <inertial>
      <origin xyz="0.012402519029617027 0.007714920695189428 1.7562179048990797e-09" rpy="0 0 0" />
      <mass value="0.0004998303821669769" />
      <inertia ixx="1.5124255824896706e-08" ixy="-2.547965438512407e-10"
        ixz="1.4306529804103833e-13" iyy="1.713520438301633e-08" iyz="-1.9604862408134825e-13"
        izz="4.935996044555037e-09" />
    </inertial>
    <visual>
      <origin xyz="0 0 0" rpy="0 0 0" />
      <geometry>
        <mesh filename="../meshes/dexhand021/l_f_link3_3_1.STL" />
      </geometry>
      <material name="">
        <color rgba="0.3 0.3 0.3 1" />
      </material>
    </visual>
    <collision>
      <origin xyz="0 0 0" rpy="0 0 0" />
      <geometry>
        <mesh filename="../meshes/dexhand021/l_f_link3_3_1.STL" />
      </geometry>
    </collision>
  </link>

  <joint name="l_f_joint3_3_1" type="fixed">
    <origin xyz="0 0 0" rpy="0 0 0" />
    <parent link="l_f_link3_3" />
    <child link="l_f_link3_3_1" />
    <axis xyz="0 0 0" />
  </joint>

  <link name="l_f_link3_3_2">
    <inertial>
      <origin xyz="0.01293824819777932 -0.004966379635972429 -5.799490468630916e-07" rpy="0 0 0" />
      <mass value="0.0009265838824928253" />
      <inertia ixx="5.343367914587497e-08" ixy="7.112721953916162e-10" ixz="4.75643671594095e-12"
        iyy="7.063684996215479e-08" iyz="-9.602248319449433e-13" izz="4.755927862545644e-08" />
    </inertial>
    <visual>
      <origin xyz="0 0 0" rpy="0 0 0" />
      <geometry>
        <mesh filename="../meshes/dexhand021/l_f_link3_3_2.STL" />
      </geometry>
      <material name="">
        <color rgba="0.9 0.9 0.9 1" />
      </material>
    </visual>
    <collision>
      <origin xyz="0 0 0" rpy="0 0 0" />
      <geometry>
        <mesh filename="../meshes/dexhand021/l_f_link3_3_2.STL" />
      </geometry>
    </collision>
  </link>

  <joint name="l_f_joint3_3_2" type="fixed">
    <origin xyz="0 0 0" rpy="0 0 0" />
    <parent link="l_f_link3_3" />
    <child link="l_f_link3_3_2" />
    <axis xyz="0 0 0" />
  </joint>

  <link name="l_f_link3_2_1">
    <inertial>
      <origin xyz="0.020377386408241372 0.00810557847230356 -1.8358250728094052e-09" rpy="0 0 0" />
      <mass value="0.0009340644343591204" />
      <inertia ixx="2.720253099758899e-08" ixy="2.31883057772797e-09" ixz="1.4872477534342653e-12"
        iyy="6.511791793427618e-08" iyz="-3.0048229347118456e-14" izz="4.1669289501701966e-08" />
    </inertial>
    <visual>
      <origin xyz="0 0 0" rpy="0 0 0" />
      <geometry>
        <mesh filename="../meshes/dexhand021/l_f_link3_2_1.STL" />
      </geometry>
      <material name="">
        <color rgba="0.3 0.3 0.3 1" />
      </material>
    </visual>
    <collision>
      <origin xyz="0 0 0" rpy="0 0 0" />
      <geometry>
        <mesh filename="../meshes/dexhand021/l_f_link3_2_1.STL" />
      </geometry>
    </collision>
  </link>

  <joint name="l_f_joint3_2_1" type="fixed">
    <origin xyz="0 0 0" rpy="0 0 0" />
    <parent link="l_f_link3_2" />
    <child link="l_f_link3_2_1" />
    <axis xyz="0 0 0" />
  </joint>

  <link name="l_f_link3_2_2">
    <inertial>
      <origin xyz="0.0218738000215815 -0.0029659448659418615 3.4265418675301415e-06" rpy="0 0 0" />
      <mass value="0.0026799629725441833" />
      <inertia ixx="2.46106262933421e-07" ixy="5.789691111700682e-09" ixz="1.3825483861862077e-10"
        iyy="6.713031343787193e-07" iyz="6.228665402430987e-11" izz="5.922202883501011e-07" />
    </inertial>
    <visual>
      <origin xyz="0 0 0" rpy="0 0 0" />
      <geometry>
        <mesh filename="../meshes/dexhand021/l_f_link3_2_2.STL" />
      </geometry>
      <material name="">
        <color rgba="0.9 0.9 0.9 1" />
      </material>
    </visual>
    <collision>
      <origin xyz="0 0 0" rpy="0 0 0" />
      <geometry>
        <mesh filename="../meshes/dexhand021/l_f_link3_2_2.STL" />
      </geometry>
    </collision>
  </link>

  <joint name="l_f_joint3_2_2" type="fixed">
    <origin xyz="0 0 0" rpy="0 0 0" />
    <parent link="l_f_link3_2" />
    <child link="l_f_link3_2_2" />
    <axis xyz="0 0 0" />
  </joint>

  <link name="l_f_link4_1">
    <inertial>
      <origin xyz="0.008006845858825355 2.4430781841519777e-05 -0.001584227844009538" rpy="0 0 0" />
      <mass value="0.003518579078981058" />
      <inertia ixx="2.3067123359244193e-07" ixy="-9.293912305486018e-10" ixz="4.890437586059445e-08"
        iyy="3.7198348222768516e-07" iyz="-1.2241592207881815e-10" izz="2.9800529593180727e-07" />
    </inertial>
    <visual>
      <origin xyz="0 0 0" rpy="0 0 0" />
      <geometry>
        <mesh filename="../meshes/dexhand021/l_f_link4_1.STL" />
      </geometry>
      <material name="">
        <color rgba="0.3 0.3 0.3 1" />
      </material>
    </visual>
    <collision>
      <origin xyz="0 0 0" rpy="0 0 0" />
      <geometry>
        <mesh filename="../meshes/dexhand021/l_f_link4_1.STL" />
      </geometry>
    </collision>
  </link>

  <joint name="l_f_joint4_1" type="revolute">
    <origin xyz="0.013688 -0.005466 0.3287" rpy="1.5708 -1.57 0" />
    <parent link="l_p_link0" />
    <child link="l_f_link4_1" />
    <axis xyz="0 0 -1" />
    <limit lower="0" upper="0.6" effort="10" velocity="1.5" />
    <joint_properties damping="0.3" friction="0.6" />
  </joint>

  <link name="l_f_link4_2">
    <inertial>
      <origin xyz="0.021444679550906676 -0.0004628949089310474 -0.0004786927089766433" rpy="0 0 0" />
      <mass value="0.004989367448655342" />
      <inertia ixx="2.064476391134477e-07" ixy="8.780455972508096e-09" ixz="-2.955798697096858e-10"
        iyy="1.0552014748310246e-06" iyz="-9.019287841432947e-10" izz="1.0401625323234898e-06" />
    </inertial>
    <visual>
      <origin xyz="0 0 0" rpy="0 0 0" />
      <geometry>
        <mesh filename="../meshes/dexhand021/l_f_link4_2.STL" />
      </geometry>
      <material name="">
        <color rgba="0.3 0.3 0.3 1" />
      </material>
    </visual>
    <collision>
      <origin xyz="0 0 0" rpy="0 0 0" />
      <geometry>
        <mesh filename="../meshes/dexhand021/l_f_link4_2.STL" />
      </geometry>
    </collision>
  </link>

  <joint name="l_f_joint4_2" type="revolute">
    <origin xyz="0.017 1.2935E-05 0" rpy="1.5708 0 0.00076086" />
    <parent link="l_f_link4_1" />
    <child link="l_f_link4_2" />
    <axis xyz="0 0 1" />
    <limit lower="0" upper="1.3" effort="10" velocity="1.5" />
    <joint_properties damping="0.3" friction="0.6" />
  </joint>

  <link name="l_f_link4_3">
    <inertial>
      <origin xyz="0.013280328692675118 -0.0006199315921702535 -1.786332165982431e-05" rpy="0 0 0" />
      <mass value="0.0033203328984136053" />
      <inertia ixx="9.569221204956855e-08" ixy="1.0826362598447793e-08"
        ixz="-1.6181713632650606e-09" iyy="3.077893159220978e-07" iyz="-8.827964274264399e-11"
        izz="3.206404029300517e-07" />
    </inertial>
    <visual>
      <origin xyz="0 0 0" rpy="0 0 0" />
      <geometry>
        <mesh filename="../meshes/dexhand021/l_f_link4_3.STL" />
      </geometry>
      <material name="">
        <color rgba="0.3 0.3 0.3 1" />
      </material>
    </visual>
    <collision>
      <origin xyz="0 0 0" rpy="0 0 0" />
      <geometry>
        <mesh filename="../meshes/dexhand021/l_f_link4_3.STL" />
      </geometry>
    </collision>
  </link>

  <joint name="l_f_joint4_3" type="revolute">
    <origin xyz="0.043 0 0" rpy="0 0 0" />
    <parent link="l_f_link4_2" />
    <child link="l_f_link4_3" />
    <axis xyz="0 0 1" />
    <limit lower="0" upper="1.3" effort="10" velocity="1.5" />
    <joint_properties damping="0.3" friction="0.6" />
  </joint>

  <link name="l_f_link4_4">
    <inertial>
      <origin xyz="0.01683572414297906 -0.002545133895002119 -2.3757912991862224e-06" rpy="0 0 0" />
      <mass value="0.004352952819355011" />
      <inertia ixx="1.7269823391299847e-07" ixy="7.185121765660952e-08" ixz="1.0129621084417013e-10"
        iyy="5.47093812718992e-07" iyz="-4.5841181436572735e-11" izz="5.330028957234553e-07" />
    </inertial>
    <visual>
      <origin xyz="0 0 0" rpy="0 0 0" />
      <geometry>
        <mesh filename="../meshes/dexhand021/l_f_link4_4.STL" />
      </geometry>
      <material name="">
        <color rgba="0.3 0.3 0.3 1" />
      </material>
    </visual>
    <collision>
      <origin xyz="0 0 0" rpy="0 0 0" />
      <geometry>
        <mesh filename="../meshes/dexhand021/l_f_link4_4.STL" />
      </geometry>
    </collision>
  </link>

  <joint name="l_f_joint4_4" type="revolute">
    <origin xyz="0.025 0 0" rpy="0 0 0" />
    <parent link="l_f_link4_3" />
    <child link="l_f_link4_4" />
    <axis xyz="0 0 1" />
    <limit lower="0" upper="1.3" effort="10" velocity="1.5" />
    <joint_properties damping="0.3" friction="0.6" />
  </joint>

  <link name="l_f_link4_4_1">
    <inertial>
      <origin xyz="0.009738422454598935 0.005930029867598804 5.184462258341419e-07" rpy="0 0 0" />
      <mass value="0.00038943301930773673" />
      <inertia ixx="1.1761888707777015e-08" ixy="-1.920937838807718e-10"
        ixz="1.1862851425294855e-12" iyy="1.3432121472446827e-08" iyz="1.5284543351057691e-13"
        izz="3.3280605712578986e-09" />
    </inertial>
    <visual>
      <origin xyz="0 0 0" rpy="0 0 0" />
      <geometry>
        <mesh filename="../meshes/dexhand021/l_f_link4_4_1.STL" />
      </geometry>
      <material name="">
        <color rgba="0.3 0.3 0.3 1" />
      </material>
    </visual>
    <collision>
      <origin xyz="0 0 0" rpy="0 0 0" />
      <geometry>
        <mesh filename="../meshes/dexhand021/l_f_link4_4_1.STL" />
      </geometry>
    </collision>
  </link>

  <joint name="l_f_joint4_4_1" type="fixed">
    <origin xyz="0 0 0" rpy="0 0 0" />
    <parent link="l_f_link4_4" />
    <child link="l_f_link4_4_1" />
    <axis xyz="0 0 0" />
  </joint>

  <link name="l_f_link4_4_2">
    <inertial>
      <origin xyz="0.015433183877996649 -0.006148726613474523 1.6634832966249432e-06" rpy="0 0 0" />
      <mass value="0.0019468121676848738" />
      <inertia ixx="1.4302405503805286e-07" ixy="4.8873098834891486e-08" ixz="-5.68060995027927e-11"
        iyy="3.262574396227582e-07" iyz="7.694528690151449e-12" izz="2.866601186317786e-07" />
    </inertial>
    <visual>
      <origin xyz="0 0 0" rpy="0 0 0" />
      <geometry>
        <mesh filename="../meshes/dexhand021/l_f_link4_4_2.STL" />
      </geometry>
      <material name="">
        <color rgba="0.9 0.9 0.9 1" />
      </material>
    </visual>
    <collision>
      <origin xyz="0 0 0" rpy="0 0 0" />
      <geometry>
        <mesh filename="../meshes/dexhand021/l_f_link4_4_2.STL" />
      </geometry>
    </collision>
  </link>

  <joint name="l_f_joint4_4_2" type="fixed">
    <origin xyz="0 0 0" rpy="0 0 0" />
    <parent link="l_f_link4_4" />
    <child link="l_f_link4_4_2" />
    <axis xyz="0 0 0" />
  </joint>

  <link name="l_f_link4_3_1">
    <inertial>
      <origin xyz="0.012402519029567714 0.00771492069507075 1.755888949884766e-09" rpy="0 0 0" />
      <mass value="0.0004998303821989261" />
      <inertia ixx="1.5124255825893704e-08" ixy="-2.547965438972332e-10"
        ixz="1.4306517121574733e-13" iyy="1.7135204383881664e-08" iyz="-1.9604892906125066e-13"
        izz="4.9359960447248284e-09" />
    </inertial>
    <visual>
      <origin xyz="0 0 0" rpy="0 0 0" />
      <geometry>
        <mesh filename="../meshes/dexhand021/l_f_link4_3_1.STL" />
      </geometry>
      <material name="">
        <color rgba="0.3 0.3 0.3 1" />
      </material>
    </visual>
    <collision>
      <origin xyz="0 0 0" rpy="0 0 0" />
      <geometry>
        <mesh filename="../meshes/dexhand021/l_f_link4_3_1.STL" />
      </geometry>
    </collision>
  </link>

  <joint name="l_f_joint4_3_1" type="fixed">
    <origin xyz="0 0 0" rpy="0 0 0" />
    <parent link="l_f_link4_3" />
    <child link="l_f_link4_3_1" />
    <axis xyz="0 0 0" />
    <joint_properties damping="0.3" friction="0.6" />
  </joint>

  <link name="l_f_link4_3_2">
    <inertial>
      <origin xyz="0.012938248197779318 -0.00496637963597243 -5.799490468624966e-07" rpy="0 0 0" />
      <mass value="0.0009265838824928249" />
      <inertia ixx="5.343367914587494e-08" ixy="7.112721953916162e-10" ixz="4.756436715934301e-12"
        iyy="7.063684996215479e-08" iyz="-9.60224831940789e-13" izz="4.755927862545644e-08" />
    </inertial>
    <visual>
      <origin xyz="0 0 0" rpy="0 0 0" />
      <geometry>
        <mesh filename="../meshes/dexhand021/l_f_link4_3_2.STL" />
      </geometry>
      <material name="">
        <color rgba="0.9 0.9 0.9 1" />
      </material>
    </visual>
    <collision>
      <origin xyz="0 0 0" rpy="0 0 0" />
      <geometry>
        <mesh filename="../meshes/dexhand021/l_f_link4_3_2.STL" />
      </geometry>
    </collision>
  </link>

  <joint name="l_f_joint4_3_2" type="fixed">
    <origin xyz="0 0 0" rpy="0 0 0" />
    <parent link="l_f_link4_3" />
    <child link="l_f_link4_3_2" />
    <axis xyz="0 0 0" />
  </joint>

  <link name="l_f_link4_2_1">
    <inertial>
      <origin xyz="0.02037738640824138 0.008105578472303553 -1.835825070918345e-09" rpy="0 0 0" />
      <mass value="0.0009340644343591187" />
      <inertia ixx="2.7202530997589e-08" ixy="2.318830577727918e-09" ixz="1.4872477534355782e-12"
        iyy="6.511791793427614e-08" iyz="-3.004822935175718e-14" izz="4.166928950170176e-08" />
    </inertial>
    <visual>
      <origin xyz="0 0 0" rpy="0 0 0" />
      <geometry>
        <mesh filename="../meshes/dexhand021/l_f_link4_2_1.STL" />
      </geometry>
      <material name="">
        <color rgba="0.3 0.3 0.3 1" />
      </material>
    </visual>
    <collision>
      <origin xyz="0 0 0" rpy="0 0 0" />
      <geometry>
        <mesh filename="../meshes/dexhand021/l_f_link4_2_1.STL" />
      </geometry>
    </collision>
  </link>

  <joint name="l_f_joint4_2_1" type="fixed">
    <origin xyz="0 0 0" rpy="0 0 0" />
    <parent link="l_f_link4_2" />
    <child link="l_f_link4_2_1" />
    <axis xyz="0 0 0" />
  </joint>

  <link name="l_f_link4_2_2">
    <inertial>
      <origin xyz="0.0218738000215815 -0.0029659448659418593 3.426541867530143e-06" rpy="0 0 0" />
      <mass value="0.002679962972544182" />
      <inertia ixx="2.4610626293342085e-07" ixy="5.789691111700501e-09" ixz="1.3825483861862083e-10"
        iyy="6.713031343787189e-07" iyz="6.228665402437367e-11" izz="5.922202883501009e-07" />
    </inertial>
    <visual>
      <origin xyz="0 0 0" rpy="0 0 0" />
      <geometry>
        <mesh filename="../meshes/dexhand021/l_f_link4_2_2.STL" />
      </geometry>
      <material name="">
        <color rgba="0.9 0.9 0.9 1" />
      </material>
    </visual>
    <collision>
      <origin xyz="0 0 0" rpy="0 0 0" />
      <geometry>
        <mesh filename="../meshes/dexhand021/l_f_link4_2_2.STL" />
      </geometry>
    </collision>
  </link>

  <joint name="l_f_joint4_2_2" type="fixed">
    <origin xyz="0 0 0" rpy="0 0 0" />
    <parent link="l_f_link4_2" />
    <child link="l_f_link4_2_2" />
    <axis xyz="0 0 0" />
  </joint>

  <link name="l_f_link5_1">
    <inertial>
      <origin xyz="0.008006845866748942 2.443078454275862e-05 -0.0015842278420174986" rpy="0 0 0" />
      <mass value="0.0035185790783407995" />
      <inertia ixx="2.3067123352468068e-07" ixy="-9.293912968394032e-10"
        ixz="4.8904375962186106e-08" iyy="3.7198348200499247e-07" iyz="-1.22415919502092e-10"
        izz="2.980052957824027e-07" />
    </inertial>
    <visual>
      <origin xyz="0 0 0" rpy="0 0 0" />
      <geometry>
        <mesh filename="../meshes/dexhand021/l_f_link5_1.STL" />
      </geometry>
      <material name="">
        <color rgba="0.3 0.3 0.3 1" />
      </material>
    </visual>
    <collision>
      <origin xyz="0 0 0" rpy="0 0 0" />
      <geometry>
        <mesh filename="../meshes/dexhand021/l_f_link5_1.STL" />
      </geometry>
    </collision>
  </link>

  <joint name="l_f_joint5_1" type="revolute">
    <origin xyz="0.037988 -0.005466 0.3147" rpy="1.5708 -1.57 0" />
    <parent link="l_p_link0" />
    <child link="l_f_link5_1" />
    <axis xyz="0 0 -1" />
    <limit lower="0" upper="0.6" effort="10" velocity="1.5" />
    <joint_properties damping="0.3" friction="0.6" />
  </joint>

  <link name="l_f_link5_2">
    <inertial>
      <origin xyz="0.021444679550906603 -0.0004628949089313295 -0.0004786927089768149" rpy="0 0 0" />
      <mass value="0.004989367448655121" />
      <inertia ixx="2.0644763911342805e-07" ixy="8.780455972482033e-09" ixz="-2.955798697224554e-10"
        iyy="1.0552014748309056e-06" iyz="-9.019287841410571e-10" izz="1.0401625323233744e-06" />
    </inertial>
    <visual>
      <origin xyz="0 0 0" rpy="0 0 0" />
      <geometry>
        <mesh filename="../meshes/dexhand021/l_f_link5_2.STL" />
      </geometry>
      <material name="">
        <color rgba="0.3 0.3 0.3 1" />
      </material>
    </visual>
    <collision>
      <origin xyz="0 0 0" rpy="0 0 0" />
      <geometry>
        <mesh filename="../meshes/dexhand021/l_f_link5_2.STL" />
      </geometry>
    </collision>
  </link>

  <joint name="l_f_joint5_2" type="revolute">
    <origin xyz="0.017 1.2935E-05 0" rpy="1.5708 0 0.00076086" />
    <parent link="l_f_link5_1" />
    <child link="l_f_link5_2" />
    <axis xyz="0 0 1" />
    <limit lower="0" upper="1.3" effort="10" velocity="1.5" />
    <joint_properties damping="0.3" friction="0.6" />
  </joint>

  <link name="l_f_link5_3">
    <inertial>
      <origin xyz="0.013280328692676044 -0.0006199315921701265 -1.786332165986752e-05" rpy="0 0 0" />
      <mass value="0.003320332898413456" />
      <inertia ixx="9.569221204956008e-08" ixy="1.0826362598447572e-08"
        ixz="-1.6181713632700206e-09" iyy="3.07789315922064e-07" iyz="-8.827964273946297e-11"
        izz="3.2064040293000583e-07" />
    </inertial>
    <visual>
      <origin xyz="0 0 0" rpy="0 0 0" />
      <geometry>
        <mesh filename="../meshes/dexhand021/l_f_link5_3.STL" />
      </geometry>
      <material name="">
        <color rgba="0.3 0.3 0.3 1" />
      </material>
    </visual>
    <collision>
      <origin xyz="0 0 0" rpy="0 0 0" />
      <geometry>
        <mesh filename="../meshes/dexhand021/l_f_link5_3.STL" />
      </geometry>
    </collision>
  </link>

  <joint name="l_f_joint5_3" type="revolute">
    <origin xyz="0.043 0 0" rpy="0 0 0" />
    <parent link="l_f_link5_2" />
    <child link="l_f_link5_3" />
    <axis xyz="0 0 1" />
    <limit lower="0" upper="1.3" effort="10" velocity="1.5" />
    <joint_properties damping="0.3" friction="0.6" />
  </joint>

  <link name="l_f_link5_4">
    <inertial>
      <origin xyz="0.016835724192886106 -0.002545133906660096 -2.3758074399037555e-06" rpy="0 0 0" />
      <mass value="0.00435295285508909" />
      <inertia ixx="1.7269823605463742e-07" ixy="7.185121819677348e-08" ixz="1.0129642341729513e-10"
        iyy="5.470938167123792e-07" iyz="-4.584115393699965e-11" izz="5.330028980408515e-07" />
    </inertial>
    <visual>
      <origin xyz="0 0 0" rpy="0 0 0" />
      <geometry>
        <mesh filename="../meshes/dexhand021/l_f_link5_4.STL" />
      </geometry>
      <material name="">
        <color rgba="0.3 0.3 0.3 1" />
      </material>
    </visual>
    <collision>
      <origin xyz="0 0 0" rpy="0 0 0" />
      <geometry>
        <mesh filename="../meshes/dexhand021/l_f_link5_4.STL" />
      </geometry>
    </collision>
  </link>

  <joint name="l_f_joint5_4" type="revolute">
    <origin xyz="0.025 0 0" rpy="0 0 0" />
    <parent link="l_f_link5_3" />
    <child link="l_f_link5_4" />
    <axis xyz="0 0 1" />
    <limit lower="0" upper="1.3" effort="10" velocity="1.5" />
    <joint_properties damping="0.3" friction="0.6" />
  </joint>

  <link name="l_f_link5_4_1">
    <inertial>
      <origin xyz="0.009738422454345728 0.005930029867607994 5.184464520486871e-07" rpy="0 0 0" />
      <mass value="0.0003894330192680038" />
      <inertia ixx="1.1761888706684732e-08" ixy="-1.9209378388773822e-10"
        ixz="1.186284566958111e-12" iyy="1.3432121470991997e-08" iyz="1.5284533404350157e-13"
        izz="3.328060570965626e-09" />
    </inertial>
    <visual>
      <origin xyz="0 0 0" rpy="0 0 0" />
      <geometry>
        <mesh filename="../meshes/dexhand021/l_f_link5_4_1.STL" />
      </geometry>
      <material name="">
        <color rgba="0.3 0.3 0.3 1" />
      </material>
    </visual>
    <collision>
      <origin xyz="0 0 0" rpy="0 0 0" />
      <geometry>
        <mesh filename="../meshes/dexhand021/l_f_link5_4_1.STL" />
      </geometry>
    </collision>
  </link>

  <joint name="l_f_joint5_4_1" type="fixed">
    <origin xyz="0 0 0" rpy="0 0 0" />
    <parent link="l_f_link5_4" />
    <child link="l_f_link5_4_1" />
    <axis xyz="0 0 0" />
  </joint>

  <link name="l_f_link5_4_2">
    <inertial>
      <origin xyz="0.015433183879573296 -0.006148726613435893 1.6634833667932593e-06" rpy="0 0 0" />
      <mass value="0.0019468121678303657" />
      <inertia ixx="1.4302405503834413e-07" ixy="4.8873098833300977e-08"
        ixz="-5.6806102385408916e-11" iyy="3.2625743968777957e-07" iyz="7.69452862032225e-12"
        izz="2.8666011869658974e-07" />
    </inertial>
    <visual>
      <origin xyz="0 0 0" rpy="0 0 0" />
      <geometry>
        <mesh filename="../meshes/dexhand021/l_f_link5_4_2.STL" />
      </geometry>
      <material name="">
        <color rgba="0.9 0.9 0.9 1" />
      </material>
    </visual>
    <collision>
      <origin xyz="0 0 0" rpy="0 0 0" />
      <geometry>
        <mesh filename="../meshes/dexhand021/l_f_link5_4_2.STL" />
      </geometry>
    </collision>
  </link>

  <joint name="l_f_joint5_4_2" type="fixed">
    <origin xyz="0 0 0" rpy="0 0 0" />
    <parent link="l_f_link5_4" />
    <child link="l_f_link5_4_2" />
    <axis xyz="0 0 0" />
  </joint>

  <link name="l_f_link5_3_1">
    <inertial>
      <origin xyz="0.01240251902961703 0.007714920695189428 1.7562179048990797e-09" rpy="0 0 0" />
      <mass value="0.0004998303821669769" />
      <inertia ixx="1.51242558248967e-08" ixy="-2.5479654385122775e-10" ixz="1.4306529804103833e-13"
        iyy="1.713520438301629e-08" iyz="-1.9604862408102513e-13" izz="4.935996044554998e-09" />
    </inertial>
    <visual>
      <origin xyz="0 0 0" rpy="0 0 0" />
      <geometry>
        <mesh filename="../meshes/dexhand021/l_f_link5_3_1.STL" />
      </geometry>
      <material name="">
        <color rgba="0.3 0.3 0.3 1" />
      </material>
    </visual>
    <collision>
      <origin xyz="0 0 0" rpy="0 0 0" />
      <geometry>
        <mesh filename="../meshes/dexhand021/l_f_link5_3_1.STL" />
      </geometry>
    </collision>
  </link>

  <joint name="l_f_joint5_3_1" type="fixed">
    <origin xyz="0 0 0" rpy="0 0 0" />
    <parent link="l_f_link5_3" />
    <child link="l_f_link5_3_1" />
    <axis xyz="0 0 0" />
  </joint>

  <link name="l_f_link5_3_2">
    <inertial>
      <origin xyz="0.01293824819777932 -0.0049663796359724266 -5.799490468630916e-07" rpy="0 0 0" />
      <mass value="0.0009265838824928253" />
      <inertia ixx="5.343367914587499e-08" ixy="7.11272195391642e-10" ixz="4.75643671594095e-12"
        iyy="7.063684996215479e-08" iyz="-9.602248319449449e-13" izz="4.7559278625456466e-08" />
    </inertial>
    <visual>
      <origin xyz="0 0 0" rpy="0 0 0" />
      <geometry>
        <mesh filename="../meshes/dexhand021/l_f_link5_3_2.STL" />
      </geometry>
      <material name="">
        <color rgba="0.9 0.9 0.9 1" />
      </material>
    </visual>
    <collision>
      <origin xyz="0 0 0" rpy="0 0 0" />
      <geometry>
        <mesh filename="../meshes/dexhand021/l_f_link5_3_2.STL" />
      </geometry>
    </collision>
  </link>

  <joint name="l_f_joint5_3_2" type="fixed">
    <origin xyz="0 0 0" rpy="0 0 0" />
    <parent link="l_f_link5_3" />
    <child link="l_f_link5_3_2" />
    <axis xyz="0 0 0" />
  </joint>

  <link name="l_f_link5_2_1">
    <inertial>
      <origin xyz="0.020377386408241372 0.008105578472303556 -1.8358250731876179e-09" rpy="0 0 0" />
      <mass value="0.0009340644343591205" />
      <inertia ixx="2.7202530997589e-08" ixy="2.318830577727892e-09" ixz="1.487247753432452e-12"
        iyy="6.511791793427614e-08" iyz="-3.0048229349551126e-14" izz="4.1669289501701814e-08" />
    </inertial>
    <visual>
      <origin xyz="0 0 0" rpy="0 0 0" />
      <geometry>
        <mesh filename="../meshes/dexhand021/l_f_link5_2_1.STL" />
      </geometry>
      <material name="">
        <color rgba="0.3 0.3 0.3 1" />
      </material>
    </visual>
    <collision>
      <origin xyz="0 0 0" rpy="0 0 0" />
      <geometry>
        <mesh filename="../meshes/dexhand021/l_f_link5_2_1.STL" />
      </geometry>
    </collision>
  </link>

  <joint name="l_f_joint5_2_1" type="fixed">
    <origin xyz="0 0 0" rpy="0 0 0" />
    <parent link="l_f_link5_2" />
    <child link="l_f_link5_2_1" />
    <axis xyz="0 0 0" />
  </joint>

  <link name="l_f_link5_2_2">
    <inertial>
      <origin xyz="0.021873800021581506 -0.0029659448659418467 3.426541867502968e-06" rpy="0 0 0" />
      <mass value="0.002679962972544193" />
      <inertia ixx="2.46106262933422e-07" ixy="5.789691111700967e-09" ixz="1.382548386171941e-10"
        iyy="6.71303134378717e-07" iyz="6.22866540244921e-11" izz="5.922202883500982e-07" />
    </inertial>
    <visual>
      <origin xyz="0 0 0" rpy="0 0 0" />
      <geometry>
        <mesh filename="../meshes/dexhand021/l_f_link5_2_2.STL" />
      </geometry>
      <material name="">
        <color rgba="0.9 0.9 0.9 1" />
      </material>
    </visual>
    <collision>
      <origin xyz="0 0 0" rpy="0 0 0" />
      <geometry>
        <mesh filename="../meshes/dexhand021/l_f_link5_2_2.STL" />
      </geometry>
    </collision>
  </link>

  <joint name="l_f_joint5_2_2" type="fixed">
    <origin xyz="0 0 0" rpy="0 0 0" />
    <parent link="l_f_link5_2" />
    <child link="l_f_link5_2_2" />
    <axis xyz="0 0 0" />
  </joint>

  <link name="l_p_link1">
    <inertial>
      <origin xyz="-0.039828367122623734 -0.05274778430354539 -0.009532289282993165" rpy="0 0 0" />
      <mass value="0.08402879470191237" />
      <inertia ixx="0.00012061000995335967" ixy="9.17811986947015e-06" ixz="-1.0617175255849679e-05"
        iyy="0.00015463827295592394" iyz="4.4918865703612454e-07" izz="3.900039912950205e-05" />
    </inertial>
    <visual>
      <origin xyz="0 0 0" rpy="0 0 0" />
      <geometry>
        <mesh filename="../meshes/dexhand021/l_p_link1.STL" />
      </geometry>
      <material name="">
        <color rgba="0.3 0.3 0.3 1" />
      </material>
    </visual>
    <collision>
      <origin xyz="0 0 0" rpy="0 0 0" />
      <geometry>
        <mesh filename="../meshes/dexhand021/l_p_link1.STL" />
      </geometry>
    </collision>
  </link>

  <joint name="l_f_joint1" type="fixed">
    <origin xyz="-0.023855 -0.031204 0.27607" rpy="0 -0.15197 -2.8876" />
    <parent link="l_p_link0" />
    <child link="l_p_link1" />
    <axis xyz="0 0 0" />
  </joint>

  <link name="l_p_link2">
    <inertial>
      <origin xyz="-0.02488492263507479 -0.007868276064529948 0.02307958050328564" rpy="0 0 0" />
      <mass value="0.07899885001313191" />
      <inertia ixx="4.9749332651746786e-05" ixy="2.9038341534341812e-05"
        ixz="-7.615778905613395e-06" iyy="0.00015619302190803325" iyz="-1.5002047733083078e-06"
        izz="0.00013058028469968588" />
    </inertial>
    <visual>
      <origin xyz="0 0 0" rpy="0 0 0" />
      <geometry>
        <mesh filename="../meshes/dexhand021/l_p_link2.STL" />
      </geometry>
      <material name="">
        <color rgba="0.9 0.9 0.9 1" />
      </material>
    </visual>
    <collision>
      <origin xyz="0 0 0" rpy="0 0 0" />
      <geometry>
        <mesh filename="../meshes/dexhand021/l_p_link2.STL" />
      </geometry>
    </collision>
  </link>

  <joint name="l_f_joint2" type="fixed">
    <origin xyz="-0.023855 -0.031204 0.27607" rpy="0 -0.15197 -2.8876" />
    <parent link="l_p_link0" />
    <child link="l_p_link2" />
    <axis xyz="0 0 0" />
  </joint>

  <link name="l_p_link3">
    <inertial>
      <origin xyz="-0.023336898526263472 -0.0010207888192092151 0.028962598242239686" rpy="0 0 0" />
      <mass value="0.04403763346723259" />
      <inertia ixx="1.6579592867138346e-05" ixy="8.971445809253096e-06" ixz="-5.369063153578631e-06"
        iyy="4.981163538329432e-05" iyz="7.898498335261686e-07" izz="3.788988071413252e-05" />
    </inertial>
    <visual>
      <origin xyz="0 0 0" rpy="0 0 0" />
      <geometry>
        <mesh filename="../meshes/dexhand021/l_p_link3.STL" />
      </geometry>
      <material name="">
        <color rgba="0.3 0.3 0.3 1" />
      </material>
    </visual>
    <collision>
      <origin xyz="0 0 0" rpy="0 0 0" />
      <geometry>
        <mesh filename="../meshes/dexhand021/l_p_link3.STL" />
      </geometry>
    </collision>
  </link>

  <joint name="l_f_joint3" type="fixed">
    <origin xyz="-0.023855 -0.031204 0.27607" rpy="0 -0.15197 -2.8876" />
    <parent link="l_p_link0" />
    <child link="l_p_link3" />
    <axis xyz="0 0 0" />
  </joint>

  <link name="l_p_link4">
    <inertial>
      <origin xyz="-0.0298413518038466 -0.008258222290757664 -0.049476921582376654" rpy="0 0 0" />
      <mass value="0.08225994389583667" />
      <inertia ixx="5.0882475719932426e-05" ixy="1.945126795867257e-05" ixz="2.3536588759717027e-06"
        iyy="0.00013859469040129445" iyz="-5.800266232654319e-06" izz="0.00011170513744198432" />
    </inertial>
    <visual>
      <origin xyz="0 0 0" rpy="0 0 0" />
      <geometry>
        <mesh filename="../meshes/dexhand021/l_p_link4.STL" />
      </geometry>
      <material name="">
        <color rgba="0.9 0.9 0.9 1" />
      </material>
    </visual>
    <collision>
      <origin xyz="0 0 0" rpy="0 0 0" />
      <geometry>
        <mesh filename="../meshes/dexhand021/l_p_link4.STL" />
      </geometry>
    </collision>
  </link>

  <joint name="l_f_joint4" type="fixed">
    <origin xyz="-0.023855 -0.031204 0.27607" rpy="0 -0.15197 -2.8876" />
    <parent link="l_p_link0" />
    <child link="l_p_link4" />
    <axis xyz="0 0 0" />
  </joint>

  <link name="l_p_link5">
    <inertial>
      <origin xyz="-0.022805157908453312 -0.0024278245134679364 -0.04288462820007344" rpy="0 0 0" />
      <mass value="0.022514206360667064" />
      <inertia ixx="6.7369327810856215e-06" ixy="5.241430166013195e-06" ixz="1.6760244119235387e-06"
        iyy="2.6534908658798778e-05" iyz="-6.111874746116537e-07" izz="2.379982124206274e-05" />
    </inertial>
    <visual>
      <origin xyz="0 0 0" rpy="0 0 0" />
      <geometry>
        <mesh filename="../meshes/dexhand021/l_p_link5.STL" />
      </geometry>
      <material name="">
        <color rgba="0.3 0.3 0.3 1" />
      </material>
    </visual>
    <collision>
      <origin xyz="0 0 0" rpy="0 0 0" />
      <geometry>
        <mesh filename="../meshes/dexhand021/l_p_link5.STL" />
      </geometry>
    </collision>
  </link>

  <joint name="l_f_joint5" type="fixed">
    <origin xyz="-0.023855 -0.031204 0.27607" rpy="0 -0.15197 -2.8876" />
    <parent link="l_p_link0" />
    <child link="l_p_link5" />
    <axis xyz="0 0 0" />
  </joint>

  <link name="l_p_link6">
    <inertial>
      <origin xyz="-0.035361125195284254 -0.04343591968543961 0.006711846346217487" rpy="0 0 0" />
      <mass value="0.11250344206877806" />
      <inertia ixx="0.0003119200809517767" ixy="5.040397379052519e-05" ixz="-2.1005345326720503e-05"
        iyy="0.0004997982676351444" iyz="4.3512292769422553e-07" izz="0.00022471126846159207" />
    </inertial>
    <visual>
      <origin xyz="0 0 0" rpy="0 0 0" />
      <geometry>
        <mesh filename="../meshes/dexhand021/l_p_link6.STL" />
      </geometry>
      <material name="">
        <color rgba="0.9 0.9 0.9 1" />
      </material>
    </visual>
    <collision>
      <origin xyz="0 0 0" rpy="0 0 0" />
      <geometry>
        <mesh filename="../meshes/dexhand021/l_p_link6.STL" />
      </geometry>
    </collision>
  </link>

  <joint name="l_f_joint6" type="fixed">
    <origin xyz="-0.023855 -0.031204 0.27607" rpy="0 -0.15197 -2.8876" />
    <parent link="l_p_link0" />
    <child link="l_p_link6" />
    <axis xyz="0 0 0" />
  </joint>

  <link name="l_f_link1_tip">
    <inertial>
      <origin xyz="0 0 0" rpy="0 0 0" />
      <mass value="0.001" />
      <inertia ixx="1.0E-09" ixy="0.0" ixz="0.0" iyy="1.0E-09" iyz="0.0" izz="1.0E-09" />
    </inertial>
    <visual>
      <origin xyz="0 0 0" rpy="0 0 0" />
      <geometry>
        <sphere radius="0.002" />
      </geometry>
      <material name="">
        <color rgba="1 0 0 1" />
      </material>
    </visual>
    <collision>
      <origin xyz="0 0 0" rpy="0 0 0" />
      <geometry>
        <sphere radius="0.002" />
      </geometry>
    </collision>
  </link>

  <joint name="l_f_joint1_tip" type="fixed">
    <origin xyz="0.035 -0.004 0" rpy="0 0 0" />
    <parent link="l_f_link1_4" />
    <child link="l_f_link1_tip" />
  </joint>

  <link name="l_f_link2_tip">
    <inertial>
      <origin xyz="0 0 0" rpy="0 0 0" />
      <mass value="0.001" />
      <inertia ixx="1.0E-09" ixy="0.0" ixz="0.0" iyy="1.0E-09" iyz="0.0" izz="1.0E-09" />
    </inertial>
    <visual>
      <origin xyz="0 0 0" rpy="0 0 0" />
      <geometry>
        <sphere radius="0.002" />
      </geometry>
      <material name="">
        <color rgba="1 0 0 1" />
      </material>
    </visual>
    <collision>
      <origin xyz="0 0 0" rpy="0 0 0" />
      <geometry>
        <sphere radius="0.002" />
      </geometry>
    </collision>
  </link>

  <joint name="l_f_joint2_tip" type="fixed">
    <origin xyz="0.035 -0.004 0" rpy="0 0 0" />
    <parent link="l_f_link2_4" />
    <child link="l_f_link2_tip" />
  </joint>

  <link name="l_f_link3_tip">
    <inertial>
      <origin xyz="0 0 0" rpy="0 0 0" />
      <mass value="0.001" />
      <inertia ixx="1.0E-09" ixy="0.0" ixz="0.0" iyy="1.0E-09" iyz="0.0" izz="1.0E-09" />
    </inertial>
    <visual>
      <origin xyz="0 0 0" rpy="0 0 0" />
      <geometry>
        <sphere radius="0.002" />
      </geometry>
      <material name="">
        <color rgba="1 0 0 1" />
      </material>
    </visual>
    <collision>
      <origin xyz="0 0 0" rpy="0 0 0" />
      <geometry>
        <sphere radius="0.002" />
      </geometry>
    </collision>
  </link>

  <joint name="l_f_joint3_tip" type="fixed">
    <origin xyz="0.035 -0.004 0" rpy="0 0 0" />
    <parent link="l_f_link3_4" />
    <child link="l_f_link3_tip" />
  </joint>

  <link name="l_f_link4_tip">
    <inertial>
      <origin xyz="0 0 0" rpy="0 0 0" />
      <mass value="0.001" />
      <inertia ixx="1.0E-09" ixy="0.0" ixz="0.0" iyy="1.0E-09" iyz="0.0" izz="1.0E-09" />
    </inertial>
    <visual>
      <origin xyz="0 0 0" rpy="0 0 0" />
      <geometry>
        <sphere radius="0.002" />
      </geometry>
      <material name="">
        <color rgba="1 0 0 1" />
      </material>
    </visual>
    <collision>
      <origin xyz="0 0 0" rpy="0 0 0" />
      <geometry>
        <sphere radius="0.002" />
      </geometry>
    </collision>
  </link>

  <joint name="l_f_joint4_tip" type="fixed">
    <origin xyz="0.035 -0.004 0" rpy="0 0 0" />
    <parent link="l_f_link4_4" />
    <child link="l_f_link4_tip" />
  </joint>

  <link name="l_f_link5_tip">
    <inertial>
      <origin xyz="0 0 0" rpy="0 0 0" />
      <mass value="0.001" />
      <inertia ixx="1.0E-09" ixy="0.0" ixz="0.0" iyy="1.0E-09" iyz="0.0" izz="1.0E-09" />
    </inertial>
    <visual>
      <origin xyz="0 0 0" rpy="0 0 0" />
      <geometry>
        <sphere radius="0.002" />
      </geometry>
      <material name="">
        <color rgba="1 0 0 1" />
      </material>
    </visual>
    <collision>
      <origin xyz="0 0 0" rpy="0 0 0" />
      <geometry>
        <sphere radius="0.002" />
      </geometry>
    </collision>
  </link>

  <joint name="l_f_joint5_tip" type="fixed">
    <origin xyz="0.035 -0.004 0" rpy="0 0 0" />
    <parent link="l_f_link5_4" />
    <child link="l_f_link5_tip" />
  </joint>

  <link name="l_f_link1_pad">
    <inertial>
      <origin xyz="0 0 0" rpy="0 0 0" />
      <mass value="0.001" />
      <inertia ixx="1.0E-09" ixy="0.0" ixz="0.0" iyy="1.0E-09" iyz="0.0" izz="1.0E-09" />
    </inertial>
    <visual>
      <origin xyz="0 0 0" rpy="0 0 0" />
      <geometry>
        <box size="0.012 0.001 0.006" />
      </geometry>
      <material name="">
        <color rgba="0 1 0 1" />
      </material>
    </visual>
    <collision>
      <origin xyz="0 0 0" rpy="0 0 0" />
      <geometry>
        <box size="0.012 0.001 0.006" />
      </geometry>
    </collision>
  </link>

  <joint name="l_f_joint1_pad" type="fixed">
    <origin xyz="0.026 0.0025 0.001" rpy="0 0 -0.45" />
    <parent link="l_f_link1_4" />
    <child link="l_f_link1_pad" />
  </joint>

  <link name="l_f_link2_pad">
    <inertial>
      <origin xyz="0 0 0" rpy="0 0 0" />
      <mass value="0.001" />
      <inertia ixx="1.0E-09" ixy="0.0" ixz="0.0" iyy="1.0E-09" iyz="0.0" izz="1.0E-09" />
    </inertial>
    <visual>
      <origin xyz="0 0 0" rpy="0 0 0" />
      <geometry>
        <box size="0.012 0.001 0.006" />
      </geometry>
      <material name="">
        <color rgba="0 1 0 1" />
      </material>
    </visual>
    <collision>
      <origin xyz="0 0 0" rpy="0 0 0" />
      <geometry>
        <box size="0.012 0.001 0.006" />
      </geometry>
    </collision>
  </link>

  <joint name="l_f_joint2_pad" type="fixed">
    <origin xyz="0.026 0.0025 0.000" rpy="0 0 -0.45" />
    <parent link="l_f_link2_4" />
    <child link="l_f_link2_pad" />
  </joint>

  <link name="l_f_link3_pad">
    <inertial>
      <origin xyz="0 0 0" rpy="0 0 0" />
      <mass value="0.001" />
      <inertia ixx="1.0E-09" ixy="0.0" ixz="0.0" iyy="1.0E-09" iyz="0.0" izz="1.0E-09" />
    </inertial>
    <visual>
      <origin xyz="0 0 0" rpy="0 0 0" />
      <geometry>
        <box size="0.012 0.001 0.006" />
      </geometry>
      <material name="">
        <color rgba="0 1 0 1" />
      </material>
    </visual>
    <collision>
      <origin xyz="0 0 0" rpy="0 0 0" />
      <geometry>
        <box size="0.012 0.001 0.006" />
      </geometry>
    </collision>
  </link>

  <joint name="l_f_joint3_pad" type="fixed">
    <origin xyz="0.026 0.0025 0.000" rpy="0 0 -0.45" />
    <parent link="l_f_link3_4" />
    <child link="l_f_link3_pad" />
  </joint>

  <link name="l_f_link4_pad">
    <inertial>
      <origin xyz="0 0 0" rpy="0 0 0" />
      <mass value="0.001" />
      <inertia ixx="1.0E-09" ixy="0.0" ixz="0.0" iyy="1.0E-09" iyz="0.0" izz="1.0E-09" />
    </inertial>
    <visual>
      <origin xyz="0 0 0" rpy="0 0 0" />
      <geometry>
        <box size="0.012 0.001 0.006" />
      </geometry>
      <material name="">
        <color rgba="0 1 0 1" />
      </material>
    </visual>
    <collision>
      <origin xyz="0 0 0" rpy="0 0 0" />
      <geometry>
        <box size="0.012 0.001 0.006" />
      </geometry>
    </collision>
  </link>

  <joint name="l_f_joint4_pad" type="fixed">
    <origin xyz="0.026 0.0025 0.000" rpy="0 0 -0.45" />
    <parent link="l_f_link4_4" />
    <child link="l_f_link4_pad" />
  </joint>

  <link name="l_f_link5_pad">
    <inertial>
      <origin xyz="0 0 0" rpy="0 0 0" />
      <mass value="0.001" />
      <inertia ixx="1.0E-09" ixy="0.0" ixz="0.0" iyy="1.0E-09" iyz="0.0" izz="1.0E-09" />
    </inertial>
    <visual>
      <origin xyz="0 0 0" rpy="0 0 0" />
      <geometry>
        <box size="0.012 0.001 0.006" />
      </geometry>
      <material name="">
        <color rgba="0 1 0 1" />
      </material>
    </visual>
    <collision>
      <origin xyz="0 0 0" rpy="0 0 0" />
      <geometry>
        <box size="0.012 0.001 0.006" />
      </geometry>
    </collision>
  </link>

  <joint name="l_f_joint5_pad" type="fixed">
    <origin xyz="0.026 0.0025 0.000" rpy="0 0 -0.45" />
    <parent link="l_f_link5_4" />
    <child link="l_f_link5_pad" />
  </joint>
</robot>
